Workbook

Sheet TAIFX
D1: 請自行建立副本，才不需要我的授權！謝謝
A4: 開盤日期 | B4: {=IF(INDIRECT(CONCATENATE("'DATA'!B", COUNT(DATA!B2:B1017)+1))+1 > TODAY(), INDIRECT(CONCATENATE("'DATA'!B", COUNT(DATA!B2:B1017)+1))+1, TODAY())} -> 46160
A5: DJ漲幅 (%) | B5: =US!B5 -> 7.51 | C5: NQ漲幅 (%) | D5: =US!D5 -> 15.56 | E5: SPY漲幅 (%) | F5: =US!F5 -> 11.33 | G5: TSM漲幅 (%) | H5: =US!H5 -> 33.5
A6: DJ權重 (%) | B6: 50 | C6: NQ權重 (%) | D6: 50 | E6: SPY權重 (%) | F6: 0 | G6: TSM權重 (%) | H6: 0
A7: 期貨預估 | B7: {=ROUND(INDIRECT(CONCATENATE("'DATA'!F", COUNT(DATA!F2:F1017)+1)) * (1 + (B5 * B6 + D5 * D6 + F5 * F6 + H5 * H6) / 100 / (B6 + D6 + F6 + H6)), 0)} -> 29800 | C7: 合理範圍 | D7: =ROUND(B7 * (1 - 0.005),0) -> 29651 | E7: ~ | F7: =ROUND(B7 * (1 + 0.005),0) -> 29949
A8: 現貨預估 | B8: =IFERROR(__xludf.DUMMYFUNCTION("ROUND(GOOGLEFINANCE(""TPE:TAIEX"") * (1 + (B5 * B6 + D5 * D6 + F5 * F6 + H5 * H6) / 100 / (B6 + D6 + F6 + H6)), 2)"),"#N/A") -> #N/A | C8: 合理範圍 | D8: =ROUND(B8 * (1 - 0.005), 2) -> #N/A | E8: ~ | F8: =ROUND(B8 * (1 + 0.005), 2) -> #N/A
A9: 單位風險 R | B9: =floor(B13 / 5,1) -> 73
A12: 20日平均震幅 | B12: 10日平均震幅 | C12: 5日平均震幅 | D12: 20日震幅標準差 | E12: 10日震幅標準差 | F12: 5日震幅標準差 | G12: 一個標準差震幅 | H12: 兩個標準差震幅 | I12: 三個標準差震幅
A13: {=AVERAGE(INDIRECT(CONCATENATE("'DATA'!H", count(DATA!H2:H1017)-18, ":H", count(DATA!H2:H1017)+1)))} -> 296.85 | B13: {=AVERAGE(INDIRECT(CONCATENATE("'DATA'!H", count(DATA!H2:H1017)-8, ":H", count(DATA!H2:H1017)+1)))} -> 368.4 | C13: {=AVERAGE(INDIRECT(CONCATENATE("'DATA'!H", count(DATA!H2:H1017)-3, ":H", count(DATA!H2:H1017)+1)))} -> 409.4 | D13: {=ROUND(STDEV(INDIRECT(CONCATENATE("'DATA'!H", count(DATA!H2:H1017)-18, ":H", count(DATA!H2:H1017)+1))), 2)} -> 153.18 | E13: {=ROUND(STDEV(INDIRECT(CONCATENATE("'DATA'!H", count(DATA!H2:H1017)-8, ":H", count(DATA!H2:H1017)+1))), 2)} -> 184.29 | F13: {=ROUND(STDEV(INDIRECT(CONCATENATE("'DATA'!H", count(DATA!H2:H1017)-3, ":H", count(DATA!H2:H1017)+1))), 2)} -> 233.67 | G13: =B13+E13 -> 552.69 | H13: =B13+2*E13 -> 736.98 | I13: =B13+3*E13 -> 921.27
A15: 週一平均震幅 | B15: 週二平均震幅 | C15: 週三平均震幅 | D15: 週四平均震幅 | E15: 週五平均震幅 | F15: 資料取樣月份數 | G15: 6
A16: =ROUND(SUMIF(DATA!A2:A400, "=1", DATA!H2:H400) / COUNTIF(DATA!A2:A400, "=1"), 2) -> 262.95 | B16: =ROUND(SUMIF(DATA!A2:A400, "=2", DATA!H2:H400) / COUNTIF(DATA!A2:A400, "=2"), 2) -> 294.58 | C16: =ROUND(SUMIF(DATA!A2:A400, "=3", DATA!H2:H400) / COUNTIF(DATA!A2:A400, "=3"), 2) -> 256.09 | D16: =ROUND(SUMIF(DATA!A2:A400, "=4", DATA!H2:H400) / COUNTIF(DATA!A2:A400, "=4"), 2) -> 217.39 | E16: =ROUND(SUMIF(DATA!A2:A400, "=5", DATA!H2:H400) / COUNTIF(DATA!A2:A400, "=5"), 2) -> 240.82
A18: 當沖目標震幅
A19: 一壘打 | B19: 二壘打 | C19: 三壘打 | D19: 全壘打 | E19: 場外全壘打
A20: {=MIN(INDIRECT(CONCATENATE("'DATA'!H", count(DATA!H2:H1017)-18, ":H", count(DATA!H2:H1017)+1)))} -> 116 | B20: {=ROUND(AVERAGEIF(INDIRECT(CONCATENATE("'DATA'!H", count(DATA!H2:H1017)-18, ":H", count(DATA!H2:H1017)+1)), "<"&A13), 1)} -> 201.6 | C20: {=AVERAGE(INDIRECT(CONCATENATE("'DATA'!H", count(DATA!H2:H1017)-18, ":H", count(DATA!H2:H1017)+1)))} -> 296.85 | D20: {=ROUND(AVERAGEIF(INDIRECT(CONCATENATE("'DATA'!H", count(DATA!H2:H1017)-18, ":H", count(DATA!H2:H1017)+1)), ">"&A13), 1)} -> 439.8 | E20: {=MAX(INDIRECT(CONCATENATE("'DATA'!H", count(DATA!H2:H1017)-18, ":H", count(DATA!H2:H1017)+1)))} -> 734
A22: 使用指南
A24: ．請按「更新」按鈕抓取最新期貨資料
A25: ．單位風險 R 可用來決定一口的停損點數，用來衡量一筆交易的 CP 值，預估獲利 / R 可知道盈虧比
A26: ．平均震幅 + 一個標準差，可以知道有 68.27% 的機率當天震幅會落在這裡面，用來預估還有多少空間上漲或下跌來決定 CP 值，甚至可以用來提早停利
A27: ．美股漲跌幅來預估台指開盤點數，用來評估台股的強弱度，有沒有方向上或幅度上的背離，來決定今天做多或做空哪方較有利
A29: 問題排除
A31: ．若有錯誤或疑問，請至原始連結查看 ChangeLog 是否有新的版本修正問題，有新版本的話，請重新建立副本
A91: =IF(ISBLANK(B91), "", WEEKDAY(B91,2)) | H91: =IF(D91 > 0, D91-E91, "") | I91: =IF(D91 > 0, AVERAGE(H87:H91), "") | J91: =IF(D91 > 0, AVERAGE(H82:H91), "") | K91: =IF(D91 > 0, AVERAGE(H72:H91), "")
A92: =IF(ISBLANK(B92), "", WEEKDAY(B92,2)) | H92: =IF(D92 > 0, D92-E92, "") | I92: =IF(D92 > 0, AVERAGE(H88:H92), "") | J92: =IF(D92 > 0, AVERAGE(H83:H92), "") | K92: =IF(D92 > 0, AVERAGE(H73:H92), "")
A93: =IF(ISBLANK(B93), "", WEEKDAY(B93,2)) | H93: =IF(D93 > 0, D93-E93, "") | I93: =IF(D93 > 0, AVERAGE(H89:H93), "") | J93: =IF(D93 > 0, AVERAGE(H84:H93), "") | K93: =IF(D93 > 0, AVERAGE(H74:H93), "")
A94: =IF(ISBLANK(B94), "", WEEKDAY(B94,2)) | H94: =IF(D94 > 0, D94-E94, "") | I94: =IF(D94 > 0, AVERAGE(H90:H94), "") | J94: =IF(D94 > 0, AVERAGE(H85:H94), "") | K94: =IF(D94 > 0, AVERAGE(H75:H94), "")
A95: =IF(ISBLANK(B95), "", WEEKDAY(B95,2)) | H95: =IF(D95 > 0, D95-E95, "") | I95: =IF(D95 > 0, AVERAGE(H91:H95), "") | J95: =IF(D95 > 0, AVERAGE(H86:H95), "") | K95: =IF(D95 > 0, AVERAGE(H76:H95), "")
A96: =IF(ISBLANK(B96), "", WEEKDAY(B96,2)) | H96: =IF(D96 > 0, D96-E96, "") | I96: =IF(D96 > 0, AVERAGE(H92:H96), "") | J96: =IF(D96 > 0, AVERAGE(H87:H96), "") | K96: =IF(D96 > 0, AVERAGE(H77:H96), "")
A97: =IF(ISBLANK(B97), "", WEEKDAY(B97,2)) | H97: =IF(D97 > 0, D97-E97, "") | I97: =IF(D97 > 0, AVERAGE(H93:H97), "") | J97: =IF(D97 > 0, AVERAGE(H88:H97), "") | K97: =IF(D97 > 0, AVERAGE(H78:H97), "")
A98: =IF(ISBLANK(B98), "", WEEKDAY(B98,2)) | H98: =IF(D98 > 0, D98-E98, "") | I98: =IF(D98 > 0, AVERAGE(H94:H98), "") | J98: =IF(D98 > 0, AVERAGE(H89:H98), "") | K98: =IF(D98 > 0, AVERAGE(H79:H98), "")
A99: =IF(ISBLANK(B99), "", WEEKDAY(B99,2)) | H99: =IF(D99 > 0, D99-E99, "") | I99: =IF(D99 > 0, AVERAGE(H95:H99), "") | J99: =IF(D99 > 0, AVERAGE(H90:H99), "") | K99: =IF(D99 > 0, AVERAGE(H80:H99), "")
A100: =IF(ISBLANK(B100), "", WEEKDAY(B100,2)) | H100: =IF(D100 > 0, D100-E100, "") | I100: =IF(D100 > 0, AVERAGE(H96:H100), "") | J100: =IF(D100 > 0, AVERAGE(H91:H100), "") | K100: =IF(D100 > 0, AVERAGE(H81:H100), "")
A101: =IF(ISBLANK(B101), "", WEEKDAY(B101,2)) | H101: =IF(D101 > 0, D101-E101, "") | I101: =IF(D101 > 0, AVERAGE(H97:H101), "") | J101: =IF(D101 > 0, AVERAGE(H92:H101), "") | K101: =IF(D101 > 0, AVERAGE(H82:H101), "")
A102: =IF(ISBLANK(B102), "", WEEKDAY(B102,2)) | H102: =IF(D102 > 0, D102-E102, "") | I102: =IF(D102 > 0, AVERAGE(H98:H102), "") | J102: =IF(D102 > 0, AVERAGE(H93:H102), "") | K102: =IF(D102 > 0, AVERAGE(H83:H102), "")
... A112: =IF(ISBLANK(B112), "", WEEKDAY(B112,2)) | H112: =IF(D112 > 0, D112-E112, "") | I112: =IF(D112 > 0, AVERAGE(H108:H112), "") | J112: =IF(D112 > 0, AVERAGE(H103:H112), "") | K112: =IF(D112 > 0, AVERAGE(H93:H112), "")
A113: =IF(ISBLANK(B113), "", WEEKDAY(B113,2)) | H113: =IF(D113 > 0, D113-E113, "") | I113: =IF(D113 > 0, AVERAGE(H109:H113), "")
G114: =IF(C114 > 0, C114-D114, "")
G115: =IF(C115 > 0, C115-D115, "")

Sheet DATA
A1: 星期幾 | B1: 日期 | C1: 開 | D1: 高 | E1: 低 | F1: 收 | G1: 成交量 | H1: 震幅 | I1: 5MA | J1: 10MA | K1: 20MA | L1: 跳空點數(0.5%) | M1: 紅黑K
A2: =IF(ISBLANK(B2), "", WEEKDAY(B2,2)) -> 5 | B2: 45779 | C2: 20488 | D2: 20710 | E2: 20469 | F2: 20677 | G2: 61777 | H2: =IF(D2 > 0, D2-E2, "") -> 241 | M2: =IF(D2>0,IF(F2-C2>0,"紅棒",IF(F2-C2<0,"黑棒","")),"") -> 紅棒
A3: =IF(ISBLANK(B3), "", WEEKDAY(B3,2)) -> 1 | B3: 45782 | C3: 20757 | D3: 20796 | E3: 20206 | F3: 20404 | G3: 97067 | H3: =IF(D3 > 0, D3-E3, "") -> 590 | L3: =IF(D3>0,IF(C3-F2>=F2*0.005,C3-F2,IF(F2-C3>=F2*0.005,C3-F2,"")),"") | M3: =IF(D3>0,IF(F3-C3>0,"紅棒",IF(F3-C3<0,"黑棒","")),"") -> 黑棒
A4: =IF(ISBLANK(B4), "", WEEKDAY(B4,2)) -> 2 | B4: 45783 | C4: 20150 | D4: 20483 | E4: 20150 | F4: 20337 | G4: 69754 | H4: =IF(D4 > 0, D4-E4, "") -> 333 | L4: =IF(D4>0,IF(C4-F3>=F3*0.005,C4-F3,IF(F3-C4>=F3*0.005,C4-F3,"")),"") -> -254 | M4: =IF(D4>0,IF(F4-C4>0,"紅棒",IF(F4-C4<0,"黑棒","")),"") -> 紅棒
A5: =IF(ISBLANK(B5), "", WEEKDAY(B5,2)) -> 3 | B5: 45784 | C5: 20440 | D5: 20560 | E5: 20265 | F5: 20381 | G5: 73631 | H5: =IF(D5 > 0, D5-E5, "") -> 295 | L5: =IF(D5>0,IF(C5-F4>=F4*0.005,C5-F4,IF(F4-C5>=F4*0.005,C5-F4,"")),"") -> 103 | M5: =IF(D5>0,IF(F5-C5>0,"紅棒",IF(F5-C5<0,"黑棒","")),"") -> 黑棒
A6: =IF(ISBLANK(B6), "", WEEKDAY(B6,2)) -> 4 | B6: 45785 | C6: 20475 | D6: 20695 | E6: 20452 | F6: 20575 | G6: 63264 | H6: =IF(D6 > 0, D6-E6, "") -> 243 | I6: =IF(D6 > 0, AVERAGE(H2:H6), "") -> 340.4 | L6: =IF(D6>0,IF(C6-F5>=F5*0.005,C6-F5,IF(F5-C6>=F5*0.005,C6-F5,"")),"") | M6: =IF(D6>0,IF(F6-C6>0,"紅棒",IF(F6-C6<0,"黑棒","")),"") -> 紅棒
A7: =IF(ISBLANK(B7), "", WEEKDAY(B7,2)) -> 5 | B7: 45786 | C7: 20649 | D7: 20872 | E7: 20596 | F7: 20848 | G7: 67856 | H7: =IF(D7 > 0, D7-E7, "") -> 276 | I7: =IF(D7 > 0, AVERAGE(H3:H7), "") -> 347.4 | L7: =IF(D7>0,IF(C7-F6>=F6*0.005,C7-F6,IF(F6-C7>=F6*0.005,C7-F6,"")),"") | M7: =IF(D7>0,IF(F7-C7>0,"紅棒",IF(F7-C7<0,"黑棒","")),"") -> 紅棒
A8: =IF(ISBLANK(B8), "", WEEKDAY(B8,2)) -> 1 | B8: 45789 | C8: 21015 | D8: 21134 | E8: 20978 | F8: 21066 | G8: 58691 | H8: =IF(D8 > 0, D8-E8, "") -> 156 | I8: =IF(D8 > 0, AVERAGE(H4:H8), "") -> 260.6 | L8: =IF(D8>0,IF(C8-F7>=F7*0.005,C8-F7,IF(F7-C8>=F7*0.005,C8-F7,"")),"") -> 167 | M8: =IF(D8>0,IF(F8-C8>0,"紅棒",IF(F8-C8<0,"黑棒","")),"") -> 紅棒
A9: =IF(ISBLANK(B9), "", WEEKDAY(B9,2)) -> 2 | B9: 45790 | C9: 21421 | D9: 21520 | E9: 21288 | F9: 21360 | G9: 61021 | H9: =IF(D9 > 0, D9-E9, "") -> 232 | I9: =IF(D9 > 0, AVERAGE(H5:H9), "") -> 240.4 | L9: =IF(D9>0,IF(C9-F8>=F8*0.005,C9-F8,IF(F8-C9>=F8*0.005,C9-F8,"")),"") -> 355 | M9: =IF(D9>0,IF(F9-C9>0,"紅棒",IF(F9-C9<0,"黑棒","")),"") -> 黑棒
A10: =IF(ISBLANK(B10), "", WEEKDAY(B10,2)) -> 3 | B10: 45791 | C10: 21677 | D10: 21787 | E10: 21579 | F10: 21768 | G10: 59116 | H10: =IF(D10 > 0, D10-E10, "") -> 208 | I10: =IF(D10 > 0, AVERAGE(H6:H10), "") -> 223 | L10: =IF(D10>0,IF(C10-F9>=F9*0.005,C10-F9,IF(F9-C10>=F9*0.005,C10-F9,"")),"") -> 317 | M10: =IF(D10>0,IF(F10-C10>0,"紅棒",IF(F10-C10<0,"黑棒","")),"") -> 紅棒
A11: =IF(ISBLANK(B11), "", WEEKDAY(B11,2)) -> 4 | B11: 45792 | C11: 21776 | D11: 21810 | E11: 21676 | F11: 21694 | G11: 45704 | H11: =IF(D11 > 0, D11-E11, "") -> 134 | I11: =IF(D11 > 0, AVERAGE(H7:H11), "") -> 201.2 | J11: =IF(D11 > 0, AVERAGE(H2:H11), "") -> 270.8 | L11: =IF(D11>0,IF(C11-F10>=F10*0.005,C11-F10,IF(F10-C11>=F10*0.005,C11-F10,"")),"") | M11: =IF(D11>0,IF(F11-C11>0,"紅棒",IF(F11-C11<0,"黑棒","")),"") -> 黑棒
A12: =IF(ISBLANK(B12), "", WEEKDAY(B12,2)) -> 5 | B12: 45793 | C12: 21775 | D12: 21878 | E12: 21679 | F12: 21821 | G12: 55404 | H12: =IF(D12 > 0, D12-E12, "") -> 199 | I12: =IF(D12 > 0, AVERAGE(H8:H12), "") -> 185.8 | J12: =IF(D12 > 0, AVERAGE(H3:H12), "") -> 266.6 | L12: =IF(D12>0,IF(C12-F11>=F11*0.005,C12-F11,IF(F11-C12>=F11*0.005,C12-F11,"")),"") | M12: =IF(D12>0,IF(F12-C12>0,"紅棒",IF(F12-C12<0,"黑棒","")),"") -> 紅棒
A13: =IF(ISBLANK(B13), "", WEEKDAY(B13,2)) -> 1 | B13: 45796 | C13: 21682 | D13: 21748 | E13: 21499 | F13: 21538 | G13: 98203 | H13: =IF(D13 > 0, D13-E13, "") -> 249 | I13: =IF(D13 > 0, AVERAGE(H9:H13), "") -> 204.4 | J13: =IF(D13 > 0, AVERAGE(H4:H13), "") -> 232.5 | L13: =IF(D13>0,IF(C13-F12>=F12*0.005,C13-F12,IF(F12-C13>=F12*0.005,C13-F12,"")),"") -> -139 | M13: =IF(D13>0,IF(F13-C13>0,"紅棒",IF(F13-C13<0,"黑棒","")),"") -> 黑棒
A14: =IF(ISBLANK(B14), "", WEEKDAY(B14,2)) -> 2 | B14: 45797 | C14: 21753 | D14: 21772 | E14: 21505 | F14: 21539 | G14: 81214 | H14: =IF(D14 > 0, D14-E14, "") -> 267 | I14: =IF(D14 > 0, AVERAGE(H10:H14), "") -> 211.4 | J14: =IF(D14 > 0, AVERAGE(H5:H14), "") -> 225.9 | L14: =IF(D14>0,IF(C14-F13>=F13*0.005,C14-F13,IF(F13-C14>=F13*0.005,C14-F13,"")),"") -> 215 | M14: =IF(D14>0,IF(F14-C14>0,"紅棒",IF(F14-C14<0,"黑棒","")),"") -> 黑棒
A15: =IF(ISBLANK(B15), "", WEEKDAY(B15,2)) -> 3 | B15: 45798 | C15: 21472 | D15: 21747 | E15: 21472 | F15: 21672 | G15: 44969 | H15: =IF(D15 > 0, D15-E15, "") -> 275 | I15: =IF(D15 > 0, AVERAGE(H11:H15), "") -> 224.8 | J15: =IF(D15 > 0, AVERAGE(H6:H15), "") -> 223.9 | L15: =IF(D15>0,IF(C15-F14>=F14*0.005,C15-F14,IF(F14-C15>=F14*0.005,C15-F14,"")),"") | M15: =IF(D15>0,IF(F15-C15>0,"紅棒",IF(F15-C15<0,"黑棒","")),"") -> 紅棒
A16: =IF(ISBLANK(B16), "", WEEKDAY(B16,2)) -> 4 | B16: 45799 | C16: 21465 | D16: 21550 | E16: 21396 | F16: 21503 | G16: 48283 | H16: =IF(D16 > 0, D16-E16, "") -> 154 | I16: =IF(D16 > 0, AVERAGE(H12:H16), "") -> 228.8 | J16: =IF(D16 > 0, AVERAGE(H7:H16), "") -> 215 | L16: =IF(D16>0,IF(C16-F15>=F15*0.005,C16-F15,IF(F15-C16>=F15*0.005,C16-F15,"")),"") -> -207 | M16: =IF(D16>0,IF(F16-C16>0,"紅棒",IF(F16-C16<0,"黑棒","")),"") -> 紅棒
A17: =IF(ISBLANK(B17), "", WEEKDAY(B17,2)) -> 5 | B17: 45800 | C17: 21558 | D17: 21640 | E17: 21372 | F17: 21470 | G17: 51667 | H17: =IF(D17 > 0, D17-E17, "") -> 268 | I17: =IF(D17 > 0, AVERAGE(H13:H17), "") -> 242.6 | J17: =IF(D17 > 0, AVERAGE(H8:H17), "") -> 214.2 | L17: =IF(D17>0,IF(C17-F16>=F16*0.005,C17-F16,IF(F16-C17>=F16*0.005,C17-F16,"")),"") | M17: =IF(D17>0,IF(F17-C17>0,"紅棒",IF(F17-C17<0,"黑棒","")),"") -> 黑棒
A18: =IF(ISBLANK(B18), "", WEEKDAY(B18,2)) -> 1 | B18: 45803 | C18: 21450 | D18: 21569 | E18: 21357 | F18: 21385 | G18: 56961 | H18: =IF(D18 > 0, D18-E18, "") -> 212 | I18: =IF(D18 > 0, AVERAGE(H14:H18), "") -> 235.2 | J18: =IF(D18 > 0, AVERAGE(H9:H18), "") -> 219.8 | L18: =IF(D18>0,IF(C18-F17>=F17*0.005,C18-F17,IF(F17-C18>=F17*0.005,C18-F17,"")),"") | M18: =IF(D18>0,IF(F18-C18>0,"紅棒",IF(F18-C18<0,"黑棒","")),"") -> 黑棒
A19: =IF(ISBLANK(B19), "", WEEKDAY(B19,2)) -> 2 | B19: 45804 | C19: 21403 | D19: 21438 | E19: 21133 | F19: 21233 | G19: 61109 | H19: =IF(D19 > 0, D19-E19, "") -> 305 | I19: =IF(D19 > 0, AVERAGE(H15:H19), "") -> 242.8 | J19: =IF(D19 > 0, AVERAGE(H10:H19), "") -> 227.1 | L19: =IF(D19>0,IF(C19-F18>=F18*0.005,C19-F18,IF(F18-C19>=F18*0.005,C19-F18,"")),"") | M19: =IF(D19>0,IF(F19-C19>0,"紅棒",IF(F19-C19<0,"黑棒","")),"") -> 黑棒
A20: =IF(ISBLANK(B20), "", WEEKDAY(B20,2)) -> 3 | B20: 45805 | C20: 21420 | D20: 21512 | E20: 21150 | F20: 21252 | G20: 69146 | H20: =IF(D20 > 0, D20-E20, "") -> 362 | I20: =IF(D20 > 0, AVERAGE(H16:H20), "") -> 260.2 | J20: =IF(D20 > 0, AVERAGE(H11:H20), "") -> 242.5 | L20: =IF(D20>0,IF(C20-F19>=F19*0.005,C20-F19,IF(F19-C20>=F19*0.005,C20-F19,"")),"") -> 187 | M20: =IF(D20>0,IF(F20-C20>0,"紅棒",IF(F20-C20<0,"黑棒","")),"") -> 黑棒
A21: =IF(ISBLANK(B21), "", WEEKDAY(B21,2)) -> 4 | B21: 45806 | C21: 21513 | D21: 21616 | E21: 21275 | F21: 21320 | G21: 76415 | H21: =IF(D21 > 0, D21-E21, "") -> 341 | I21: =IF(D21 > 0, AVERAGE(H17:H21), "") -> 297.6 | J21: =IF(D21 > 0, AVERAGE(H12:H21), "") -> 263.2 | K21: =IF(D21 > 0, AVERAGE(H2:H21), "") -> 267 | L21: =IF(D21>0,IF(C21-F20>=F20*0.005,C21-F20,IF(F20-C21>=F20*0.005,C21-F20,"")),"") -> 261 | M21: =IF(D21>0,IF(F21-C21>0,"紅棒",IF(F21-C21<0,"黑棒","")),"") -> 黑棒
A22: =IF(ISBLANK(B22), "", WEEKDAY(B22,2)) -> 1 | B22: 45810 | C22: 20976 | D22: 21049 | E22: 20790 | F22: 20866 | G22: 66441 | H22: =IF(D22 > 0, D22-E22, "") -> 259 | I22: =IF(D22 > 0, AVERAGE(H18:H22), "") -> 295.8 | J22: =IF(D22 > 0, AVERAGE(H13:H22), "") -> 269.2 | K22: =IF(D22 > 0, AVERAGE(H3:H22), "") -> 267.9 | L22: =IF(D22>0,IF(C22-F21>=F21*0.005,C22-F21,IF(F21-C22>=F21*0.005,C22-F21,"")),"") -> -344 | M22: =IF(D22>0,IF(F22-C22>0,"紅棒",IF(F22-C22<0,"黑棒","")),"") -> 黑棒
A23: =IF(ISBLANK(B23), "", WEEKDAY(B23,2)) -> 2 | B23: 45811 | C23: 21034 | D23: 21221 | E23: 20955 | F23: 20971 | G23: 64909 | H23: =IF(D23 > 0, D23-E23, "") -> 266 | I23: =IF(D23 > 0, AVERAGE(H19:H23), "") -> 306.6 | J23: =IF(D23 > 0, AVERAGE(H14:H23), "") -> 270.9 | K23: =IF(D23 > 0, AVERAGE(H4:H23), "") -> 251.7 | L23: =IF(D23>0,IF(C23-F22>=F22*0.005,C23-F22,IF(F22-C23>=F22*0.005,C23-F22,"")),"") -> 168 | M23: =IF(D23>0,IF(F23-C23>0,"紅棒",IF(F23-C23<0,"黑棒","")),"") -> 黑棒
A24: =IF(ISBLANK(B24), "", WEEKDAY(B24,2)) -> 3 | B24: 45812 | C24: 21280 | D24: 21533 | E24: 21261 | F24: 21482 | G24: 61616 | H24: =IF(D24 > 0, D24-E24, "") -> 272 | I24: =IF(D24 > 0, AVERAGE(H20:H24), "") -> 300 | J24: =IF(D24 > 0, AVERAGE(H15:H24), "") -> 271.4 | K24: =IF(D24 > 0, AVERAGE(H5:H24), "") -> 248.65 | L24: =IF(D24>0,IF(C24-F23>=F23*0.005,C24-F23,IF(F23-C24>=F23*0.005,C24-F23,"")),"") -> 309 | M24: =IF(D24>0,IF(F24-C24>0,"紅棒",IF(F24-C24<0,"黑棒","")),"") -> 紅棒
A25: =IF(ISBLANK(B25), "", WEEKDAY(B25,2)) -> 4 | B25: 45813 | C25: 21589 | D25: 21677 | E25: 21512 | F25: 21553 | G25: 46482 | H25: =IF(D25 > 0, D25-E25, "") -> 165 | I25: =IF(D25 > 0, AVERAGE(H21:H25), "") -> 260.6 | J25: =IF(D25 > 0, AVERAGE(H16:H25), "") -> 260.4 | K25: =IF(D25 > 0, AVERAGE(H6:H25), "") -> 242.15 | L25: =IF(D25>0,IF(C25-F24>=F24*0.005,C25-F24,IF(F24-C25>=F24*0.005,C25-F24,"")),"") | M25: =IF(D25>0,IF(F25-C25>0,"紅棒",IF(F25-C25<0,"黑棒","")),"") -> 黑棒
A26: =IF(ISBLANK(B26), "", WEEKDAY(B26,2)) -> 5 | B26: 45814 | C26: 21599 | D26: 21630 | E26: 21513 | F26: 21578 | G26: 37655 | H26: =IF(D26 > 0, D26-E26, "") -> 117 | I26: =IF(D26 > 0, AVERAGE(H22:H26), "") -> 215.8 | J26: =IF(D26 > 0, AVERAGE(H17:H26), "") -> 256.7 | K26: =IF(D26 > 0, AVERAGE(H7:H26), "") -> 235.85 | L26: =IF(D26>0,IF(C26-F25>=F25*0.005,C26-F25,IF(F25-C26>=F25*0.005,C26-F25,"")),"") | M26: =IF(D26>0,IF(F26-C26>0,"紅棒",IF(F26-C26<0,"黑棒","")),"") -> 黑棒
A27: =IF(ISBLANK(B27), "", WEEKDAY(B27,2)) -> 1 | B27: 45817 | C27: 21663 | D27: 21788 | E27: 21626 | F27: 21727 | G27: 43471 | H27: =IF(D27 > 0, D27-E27, "") -> 162 | I27: =IF(D27 > 0, AVERAGE(H23:H27), "") -> 196.4 | J27: =IF(D27 > 0, AVERAGE(H18:H27), "") -> 246.1 | K27: =IF(D27 > 0, AVERAGE(H8:H27), "") -> 230.15 | L27: =IF(D27>0,IF(C27-F26>=F26*0.005,C27-F26,IF(F26-C27>=F26*0.005,C27-F26,"")),"") | M27: =IF(D27>0,IF(F27-C27>0,"紅棒",IF(F27-C27<0,"黑棒","")),"") -> 紅棒
A28: =IF(ISBLANK(B28), "", WEEKDAY(B28,2)) -> 2 | B28: 45818 | C28: 21879 | D28: 22236 | E28: 21850 | F28: 22113 | G28: 70320 | H28: =IF(D28 > 0, D28-E28, "") -> 386 | I28: =IF(D28 > 0, AVERAGE(H24:H28), "") -> 220.4 | J28: =IF(D28 > 0, AVERAGE(H19:H28), "") -> 263.5 | K28: =IF(D28 > 0, AVERAGE(H9:H28), "") -> 241.65 | L28: =IF(D28>0,IF(C28-F27>=F27*0.005,C28-F27,IF(F27-C28>=F27*0.005,C28-F27,"")),"") -> 152 | M28: =IF(D28>0,IF(F28-C28>0,"紅棒",IF(F28-C28<0,"黑棒","")),"") -> 紅棒
A29: =IF(ISBLANK(B29), "", WEEKDAY(B29,2)) -> 3 | B29: 45819 | C29: 22296 | D29: 22355 | E29: 22190 | F29: 22351 | G29: 53385 | H29: =IF(D29 > 0, D29-E29, "") -> 165 | I29: =IF(D29 > 0, AVERAGE(H25:H29), "") -> 199 | J29: =IF(D29 > 0, AVERAGE(H20:H29), "") -> 249.5 | K29: =IF(D29 > 0, AVERAGE(H10:H29), "") -> 238.3 | L29: =IF(D29>0,IF(C29-F28>=F28*0.005,C29-F28,IF(F28-C29>=F28*0.005,C29-F28,"")),"") -> 183 | M29: =IF(D29>0,IF(F29-C29>0,"紅棒",IF(F29-C29<0,"黑棒","")),"") -> 紅棒
A30: =IF(ISBLANK(B30), "", WEEKDAY(B30,2)) -> 4 | B30: 45820 | C30: 22315 | D30: 22329 | E30: 22214 | F30: 22252 | G30: 43973 | H30: =IF(D30 > 0, D30-E30, "") -> 115 | I30: =IF(D30 > 0, AVERAGE(H26:H30), "") -> 189 | J30: =IF(D30 > 0, AVERAGE(H21:H30), "") -> 224.8 | K30: =IF(D30 > 0, AVERAGE(H11:H30), "") -> 233.65 | L30: =IF(D30>0,IF(C30-F29>=F29*0.005,C30-F29,IF(F29-C30>=F29*0.005,C30-F29,"")),"") | M30: =IF(D30>0,IF(F30-C30>0,"紅棒",IF(F30-C30<0,"黑棒","")),"") -> 黑棒
A31: =IF(ISBLANK(B31), "", WEEKDAY(B31,2)) -> 5 | B31: 45821 | C31: 21954 | D31: 22139 | E31: 21893 | F31: 21940 | G31: 87803 | H31: =IF(D31 > 0, D31-E31, "") -> 246 | I31: =IF(D31 > 0, AVERAGE(H27:H31), "") -> 214.8 | J31: =IF(D31 > 0, AVERAGE(H22:H31), "") -> 215.3 | K31: =IF(D31 > 0, AVERAGE(H12:H31), "") -> 239.25 | L31: =IF(D31>0,IF(C31-F30>=F30*0.005,C31-F30,IF(F30-C31>=F30*0.005,C31-F30,"")),"") -> -298 | M31: =IF(D31>0,IF(F31-C31>0,"紅棒",IF(F31-C31<0,"黑棒","")),"") -> 黑棒
A32: =IF(ISBLANK(B32), "", WEEKDAY(B32,2)) -> 1 | B32: 45824 | C32: 22030 | D32: 22061 | E32: 21868 | F32: 22032 | G32: 95307 | H32: =IF(D32 > 0, D32-E32, "") -> 193 | I32: =IF(D32 > 0, AVERAGE(H28:H32), "") -> 221 | J32: =IF(D32 > 0, AVERAGE(H23:H32), "") -> 208.7 | K32: =IF(D32 > 0, AVERAGE(H13:H32), "") -> 238.95 | L32: =IF(D32>0,IF(C32-F31>=F31*0.005,C32-F31,IF(F31-C32>=F31*0.005,C32-F31,"")),"") | M32: =IF(D32>0,IF(F32-C32>0,"紅棒",IF(F32-C32<0,"黑棒","")),"") -> 紅棒
... A115: =IF(ISBLANK(B115), "", WEEKDAY(B115,2)) -> 2 | B115: 45944 | C115: 27269 | D115: 27450 | E115: 26716 | F115: 26718 | G115: 122162 | H115: =IF(D115 > 0, D115-E115, "") -> 734 | I115: =IF(D115 > 0, AVERAGE(H111:H115), "") -> 409.4 | J115: =IF(D115 > 0, AVERAGE(H106:H115), "") -> 368.4 | K115: =IF(D115 > 0, AVERAGE(H96:H115), "") -> 296.85 | L115: =IF(D115>0,IF(C115-F114>=F114*0.005,C115-F114,IF(F114-C115>=F114*0.005,C115-F114,"")),"") -> 365 | M115: =IF(D115>0,IF(F115-C115>0,"紅棒",IF(F115-C115<0,"黑棒","")),"") -> 黑棒
A116: =IF(ISBLANK(B116), "", WEEKDAY(B116,2)) | H116: =IF(D116 > 0, D116-E116, "") | I116: =IF(D116 > 0, AVERAGE(H112:H116), "") | J116: =IF(D116 > 0, AVERAGE(H107:H116), "") | K116: =IF(D116 > 0, AVERAGE(H97:H116), "") | L116: =IF(D116>0,IF(C116-F115>=F115*0.005,C116-F115,IF(F115-C116>=F115*0.005,C116-F115,"")),"") | M116: =IF(D116>0,IF(F116-C116>0,"紅棒",IF(F116-C116<0,"黑棒","")),"")
A117: =IF(ISBLANK(B117), "", WEEKDAY(B117,2)) | H117: =IF(D117 > 0, D117-E117, "") | I117: =IF(D117 > 0, AVERAGE(H113:H117), "") | J117: =IF(D117 > 0, AVERAGE(H108:H117), "") | K117: =IF(D117 > 0, AVERAGE(H98:H117), "") | L117: =IF(D117>0,IF(C117-F116>=F116*0.005,C117-F116,IF(F116-C117>=F116*0.005,C117-F116,"")),"") | M117: =IF(D117>0,IF(F117-C117>0,"紅棒",IF(F117-C117<0,"黑棒","")),"")
A118: =IF(ISBLANK(B118), "", WEEKDAY(B118,2)) | H118: =IF(D118 > 0, D118-E118, "") | I118: =IF(D118 > 0, AVERAGE(H114:H118), "") | J118: =IF(D118 > 0, AVERAGE(H109:H118), "") | K118: =IF(D118 > 0, AVERAGE(H99:H118), "") | L118: =IF(D118>0,IF(C118-F117>=F117*0.005,C118-F117,IF(F117-C118>=F117*0.005,C118-F117,"")),"") | M118: =IF(D118>0,IF(F118-C118>0,"紅棒",IF(F118-C118<0,"黑棒","")),"")
A119: =IF(ISBLANK(B119), "", WEEKDAY(B119,2)) | H119: =IF(D119 > 0, D119-E119, "") | I119: =IF(D119 > 0, AVERAGE(H115:H119), "") | J119: =IF(D119 > 0, AVERAGE(H110:H119), "") | K119: =IF(D119 > 0, AVERAGE(H100:H119), "") | L119: =IF(D119>0,IF(C119-F118>=F118*0.005,C119-F118,IF(F118-C119>=F118*0.005,C119-F118,"")),"") | M119: =IF(D119>0,IF(F119-C119>0,"紅棒",IF(F119-C119<0,"黑棒","")),"")
A120: =IF(ISBLANK(B120), "", WEEKDAY(B120,2)) | H120: =IF(D120 > 0, D120-E120, "") | I120: =IF(D120 > 0, AVERAGE(H116:H120), "") | J120: =IF(D120 > 0, AVERAGE(H111:H120), "") | K120: =IF(D120 > 0, AVERAGE(H101:H120), "") | L120: =IF(D120>0,IF(C120-F119>=F119*0.005,C120-F119,IF(F119-C120>=F119*0.005,C120-F119,"")),"") | M120: =IF(D120>0,IF(F120-C120>0,"紅棒",IF(F120-C120<0,"黑棒","")),"")
A121: =IF(ISBLANK(B121), "", WEEKDAY(B121,2)) | H121: =IF(D121 > 0, D121-E121, "") | I121: =IF(D121 > 0, AVERAGE(H117:H121), "") | J121: =IF(D121 > 0, AVERAGE(H112:H121), "") | K121: =IF(D121 > 0, AVERAGE(H102:H121), "") | L121: =IF(D121>0,IF(C121-F120>=F120*0.005,C121-F120,IF(F120-C121>=F120*0.005,C121-F120,"")),"") | M121: =IF(D121>0,IF(F121-C121>0,"紅棒",IF(F121-C121<0,"黑棒","")),"")
A122: =IF(ISBLANK(B122), "", WEEKDAY(B122,2)) | H122: =IF(D122 > 0, D122-E122, "") | I122: =IF(D122 > 0, AVERAGE(H118:H122), "") | J122: =IF(D122 > 0, AVERAGE(H113:H122), "") | K122: =IF(D122 > 0, AVERAGE(H103:H122), "") | L122: =IF(D122>0,IF(C122-F121>=F121*0.005,C122-F121,IF(F121-C122>=F121*0.005,C122-F121,"")),"") | M122: =IF(D122>0,IF(F122-C122>0,"紅棒",IF(F122-C122<0,"黑棒","")),"")
...

Sheet US
A1: 此表格僅用來計算台股最後一個交易日到本日的美股行情， 用來計算中間漲跌幅總合，請勿修改此頁 | I1: GOOGLEFINANCE 中的日期是以 UTC 中午時間為準 - 臺灣時間晚上 8 點
A3: 道瓊 | C3: 那斯達克 | E3: 標普500 | G3: 臺積電 ADR
A4: =IFERROR(__xludf.DUMMYFUNCTION("SPARKLINE(INDEX(GOOGLEFINANCE(""INDEXDJX:.DJI"",""price"",workday(TODAY(),-90),TODAY()),,2),{""charttype"",""line""})"),"") | C4: =IFERROR(__xludf.DUMMYFUNCTION("SPARKLINE(INDEX(GOOGLEFINANCE(""INDEXNASDAQ:.IXIC"",""price"",workday(TODAY(),-90),TODAY()),,2),{""charttype"",""line""})"),"") | E4: =IFERROR(__xludf.DUMMYFUNCTION("SPARKLINE(INDEX(GOOGLEFINANCE(""INDEXSP:.INX"",""price"",workday(TODAY(),-90),TODAY()),,2),{""charttype"",""line""})"),"") | G4: =IFERROR(__xludf.DUMMYFUNCTION("SPARKLINE(INDEX(GOOGLEFINANCE(""NYSE:TSM"",""price"",workday(TODAY(),-90),TODAY()),,2),{""charttype"",""line""})"),"")
A5: 總合漲幅(%) | B5: =IF(B9 > 0, ROUND((B6 - B7) * 100 / B7, 2), 0) -> 7.51 | C5: 總合漲幅(%) | D5: =IF(D9 > 0, ROUND((D6 - D7) * 100 / D7, 2), 0) -> 15.56 | E5: 總合漲幅(%) | F5: =IF(F9 > 0, ROUND((F6 - F7) * 100 / F7, 2), 0) -> 11.33 | G5: 總合漲幅(%) | H5: =IF(H9 > 0, ROUND((H6 - H7) * 100 / H7, 2), 0) -> 33.5
A6: 最新價格 | B6: =IFERROR(__xludf.DUMMYFUNCTION("GOOGLEFINANCE(""INDEXDJX:.DJI"")"),49526.17) -> 49526.17 | C6: 最新價格 | D6: =IFERROR(__xludf.DUMMYFUNCTION("GOOGLEFINANCE(""INDEXNASDAQ:.IXIC"")"),26225.15) -> 26225.15 | E6: 最新價格 | F6: =IFERROR(__xludf.DUMMYFUNCTION("GOOGLEFINANCE(""INDEXSP:.INX"")"),7408.5) -> 7408.5 | G6: 最新價格 | H6: =IFERROR(__xludf.DUMMYFUNCTION("GOOGLEFINANCE(""NYSE:TSM"")"),404.35) -> 404.35
A7: 參考價格 | B7: {=INDIRECT(CONCATENATE("B", match(INDIRECT(CONCATENATE("'DATA'!B", COUNT(DATA!B2:B1007)+1)), A9:A52)+8))} -> 46067.58 | C7: 參考價格 | D7: {=INDIRECT(CONCATENATE("D", match(INDIRECT(CONCATENATE("'DATA'!B", COUNT(DATA!B2:B1007)+1)), A9:A52)+8))} -> 22694.61 | E7: 參考價格 | F7: {=INDIRECT(CONCATENATE("F", match(INDIRECT(CONCATENATE("'DATA'!B", COUNT(DATA!D2:D1007)+1)), C9:C52)+8))} -> 6654.72 | G7: 參考價格 | H7: {=INDIRECT(CONCATENATE("H", match(INDIRECT(CONCATENATE("'DATA'!B", COUNT(DATA!F2:F1007)+1)), E9:E52)+8))} -> 302.89
A8: =IFERROR(__xludf.DUMMYFUNCTION("GOOGLEFINANCE(""INDEXDJX:.DJI"", ""price"", INDIRECT(CONCATENATE(""'DATA'!B"", COUNT(DATA!B2:B1007)-20)), TODAY())"),"Date") -> Date | B8: =IFERROR(__xludf.DUMMYFUNCTION("""COMPUTED_VALUE"""),"Close") -> Close | C8: =IFERROR(__xludf.DUMMYFUNCTION("GOOGLEFINANCE(""INDEXNASDAQ:.IXIC"", ""price"", INDIRECT(CONCATENATE(""'DATA'!B"", COUNT(DATA!B2:B1007)-20)), TODAY())"),"Date") -> Date | D8: =IFERROR(__xludf.DUMMYFUNCTION("""COMPUTED_VALUE"""),"Close") -> Close | E8: =IFERROR(__xludf.DUMMYFUNCTION("GOOGLEFINANCE(""INDEXSP:.INX"", ""price"", INDIRECT(CONCATENATE(""'DATA'!B"", COUNT(DATA!D2:D1007)-20)), TODAY())"),"Date") -> Date | F8: =IFERROR(__xludf.DUMMYFUNCTION("""COMPUTED_VALUE"""),"Close") -> Close | G8: =IFERROR(__xludf.DUMMYFUNCTION("GOOGLEFINANCE(""NYSE:TSM"", ""price"", INDIRECT(CONCATENATE(""'DATA'!B"", COUNT(DATA!F2:F1007)-20)), TODAY())"),"Date") -> Date | H8: =IFERROR(__xludf.DUMMYFUNCTION("""COMPUTED_VALUE"""),"Close") -> Close
A9: =IFERROR(__xludf.DUMMYFUNCTION("""COMPUTED_VALUE"""),45910.66666666667) -> 45910.667 | B9: =IFERROR(__xludf.DUMMYFUNCTION("""COMPUTED_VALUE"""),45490.92) -> 45490.92 | C9: =IFERROR(__xludf.DUMMYFUNCTION("""COMPUTED_VALUE"""),45910.66666666667) -> 45910.667 | D9: =IFERROR(__xludf.DUMMYFUNCTION("""COMPUTED_VALUE"""),21886.06) -> 21886.06 | E9: =IFERROR(__xludf.DUMMYFUNCTION("""COMPUTED_VALUE"""),45910.66666666667) -> 45910.667 | F9: =IFERROR(__xludf.DUMMYFUNCTION("""COMPUTED_VALUE"""),6532.04) -> 6532.04 | G9: =IFERROR(__xludf.DUMMYFUNCTION("""COMPUTED_VALUE"""),45910.66666666667) -> 45910.667 | H9: =IFERROR(__xludf.DUMMYFUNCTION("""COMPUTED_VALUE"""),260.44) -> 260.44
A10: =IFERROR(__xludf.DUMMYFUNCTION("""COMPUTED_VALUE"""),45911.66666666667) -> 45911.667 | B10: =IFERROR(__xludf.DUMMYFUNCTION("""COMPUTED_VALUE"""),46108.0) -> 46108 | C10: =IFERROR(__xludf.DUMMYFUNCTION("""COMPUTED_VALUE"""),45911.66666666667) -> 45911.667 | D10: =IFERROR(__xludf.DUMMYFUNCTION("""COMPUTED_VALUE"""),22043.08) -> 22043.08 | E10: =IFERROR(__xludf.DUMMYFUNCTION("""COMPUTED_VALUE"""),45911.66666666667) -> 45911.667 | F10: =IFERROR(__xludf.DUMMYFUNCTION("""COMPUTED_VALUE"""),6587.47) -> 6587.47 | G10: =IFERROR(__xludf.DUMMYFUNCTION("""COMPUTED_VALUE"""),45911.66666666667) -> 45911.667 | H10: =IFERROR(__xludf.DUMMYFUNCTION("""COMPUTED_VALUE"""),258.91) -> 258.91
A11: =IFERROR(__xludf.DUMMYFUNCTION("""COMPUTED_VALUE"""),45912.66666666667) -> 45912.667 | B11: =IFERROR(__xludf.DUMMYFUNCTION("""COMPUTED_VALUE"""),45834.22) -> 45834.22 | C11: =IFERROR(__xludf.DUMMYFUNCTION("""COMPUTED_VALUE"""),45912.66666666667) -> 45912.667 | D11: =IFERROR(__xludf.DUMMYFUNCTION("""COMPUTED_VALUE"""),22141.1) -> 22141.1 | E11: =IFERROR(__xludf.DUMMYFUNCTION("""COMPUTED_VALUE"""),45912.66666666667) -> 45912.667 | F11: =IFERROR(__xludf.DUMMYFUNCTION("""COMPUTED_VALUE"""),6584.29) -> 6584.29 | G11: =IFERROR(__xludf.DUMMYFUNCTION("""COMPUTED_VALUE"""),45912.66666666667) -> 45912.667 | H11: =IFERROR(__xludf.DUMMYFUNCTION("""COMPUTED_VALUE"""),259.33) -> 259.33
A12: =IFERROR(__xludf.DUMMYFUNCTION("""COMPUTED_VALUE"""),45915.66666666667) -> 45915.667 | B12: =IFERROR(__xludf.DUMMYFUNCTION("""COMPUTED_VALUE"""),45883.45) -> 45883.45 | C12: =IFERROR(__xludf.DUMMYFUNCTION("""COMPUTED_VALUE"""),45915.66666666667) -> 45915.667 | D12: =IFERROR(__xludf.DUMMYFUNCTION("""COMPUTED_VALUE"""),22348.75) -> 22348.75 | E12: =IFERROR(__xludf.DUMMYFUNCTION("""COMPUTED_VALUE"""),45915.66666666667) -> 45915.667 | F12: =IFERROR(__xludf.DUMMYFUNCTION("""COMPUTED_VALUE"""),6615.28) -> 6615.28 | G12: =IFERROR(__xludf.DUMMYFUNCTION("""COMPUTED_VALUE"""),45915.66666666667) -> 45915.667 | H12: =IFERROR(__xludf.DUMMYFUNCTION("""COMPUTED_VALUE"""),261.38) -> 261.38
A13: =IFERROR(__xludf.DUMMYFUNCTION("""COMPUTED_VALUE"""),45916.66666666667) -> 45916.667 | B13: =IFERROR(__xludf.DUMMYFUNCTION("""COMPUTED_VALUE"""),45757.9) -> 45757.9 | C13: =IFERROR(__xludf.DUMMYFUNCTION("""COMPUTED_VALUE"""),45916.66666666667) -> 45916.667 | D13: =IFERROR(__xludf.DUMMYFUNCTION("""COMPUTED_VALUE"""),22333.96) -> 22333.96 | E13: =IFERROR(__xludf.DUMMYFUNCTION("""COMPUTED_VALUE"""),45916.66666666667) -> 45916.667 | F13: =IFERROR(__xludf.DUMMYFUNCTION("""COMPUTED_VALUE"""),6606.76) -> 6606.76 | G13: =IFERROR(__xludf.DUMMYFUNCTION("""COMPUTED_VALUE"""),45916.66666666667) -> 45916.667 | H13: =IFERROR(__xludf.DUMMYFUNCTION("""COMPUTED_VALUE"""),262.06) -> 262.06
A14: =IFERROR(__xludf.DUMMYFUNCTION("""COMPUTED_VALUE"""),45917.66666666667) -> 45917.667 | B14: =IFERROR(__xludf.DUMMYFUNCTION("""COMPUTED_VALUE"""),46018.32) -> 46018.32 | C14: =IFERROR(__xludf.DUMMYFUNCTION("""COMPUTED_VALUE"""),45917.66666666667) -> 45917.667 | D14: =IFERROR(__xludf.DUMMYFUNCTION("""COMPUTED_VALUE"""),22261.33) -> 22261.33 | E14: =IFERROR(__xludf.DUMMYFUNCTION("""COMPUTED_VALUE"""),45917.66666666667) -> 45917.667 | F14: =IFERROR(__xludf.DUMMYFUNCTION("""COMPUTED_VALUE"""),6600.35) -> 6600.35 | G14: =IFERROR(__xludf.DUMMYFUNCTION("""COMPUTED_VALUE"""),45917.66666666667) -> 45917.667 | H14: =IFERROR(__xludf.DUMMYFUNCTION("""COMPUTED_VALUE"""),262.79) -> 262.79
A15: =IFERROR(__xludf.DUMMYFUNCTION("""COMPUTED_VALUE"""),45918.66666666667) -> 45918.667 | B15: =IFERROR(__xludf.DUMMYFUNCTION("""COMPUTED_VALUE"""),46142.42) -> 46142.42 | C15: =IFERROR(__xludf.DUMMYFUNCTION("""COMPUTED_VALUE"""),45918.66666666667) -> 45918.667 | D15: =IFERROR(__xludf.DUMMYFUNCTION("""COMPUTED_VALUE"""),22470.73) -> 22470.73 | E15: =IFERROR(__xludf.DUMMYFUNCTION("""COMPUTED_VALUE"""),45918.66666666667) -> 45918.667 | F15: =IFERROR(__xludf.DUMMYFUNCTION("""COMPUTED_VALUE"""),6631.96) -> 6631.96 | G15: =IFERROR(__xludf.DUMMYFUNCTION("""COMPUTED_VALUE"""),45918.66666666667) -> 45918.667 | H15: =IFERROR(__xludf.DUMMYFUNCTION("""COMPUTED_VALUE"""),268.64) -> 268.64
A16: =IFERROR(__xludf.DUMMYFUNCTION("""COMPUTED_VALUE"""),45919.66666666667) -> 45919.667 | B16: =IFERROR(__xludf.DUMMYFUNCTION("""COMPUTED_VALUE"""),46315.27) -> 46315.27 | C16: =IFERROR(__xludf.DUMMYFUNCTION("""COMPUTED_VALUE"""),45919.66666666667) -> 45919.667 | D16: =IFERROR(__xludf.DUMMYFUNCTION("""COMPUTED_VALUE"""),22631.48) -> 22631.48 | E16: =IFERROR(__xludf.DUMMYFUNCTION("""COMPUTED_VALUE"""),45919.66666666667) -> 45919.667 | F16: =IFERROR(__xludf.DUMMYFUNCTION("""COMPUTED_VALUE"""),6664.36) -> 6664.36 | G16: =IFERROR(__xludf.DUMMYFUNCTION("""COMPUTED_VALUE"""),45919.66666666667) -> 45919.667 | H16: =IFERROR(__xludf.DUMMYFUNCTION("""COMPUTED_VALUE"""),264.87) -> 264.87
A17: =IFERROR(__xludf.DUMMYFUNCTION("""COMPUTED_VALUE"""),45922.66666666667) -> 45922.667 | B17: =IFERROR(__xludf.DUMMYFUNCTION("""COMPUTED_VALUE"""),46381.54) -> 46381.54 | C17: =IFERROR(__xludf.DUMMYFUNCTION("""COMPUTED_VALUE"""),45922.66666666667) -> 45922.667 | D17: =IFERROR(__xludf.DUMMYFUNCTION("""COMPUTED_VALUE"""),22788.98) -> 22788.98 | E17: =IFERROR(__xludf.DUMMYFUNCTION("""COMPUTED_VALUE"""),45922.66666666667) -> 45922.667 | F17: =IFERROR(__xludf.DUMMYFUNCTION("""COMPUTED_VALUE"""),6693.75) -> 6693.75 | G17: =IFERROR(__xludf.DUMMYFUNCTION("""COMPUTED_VALUE"""),45922.66666666667) -> 45922.667 | H17: =IFERROR(__xludf.DUMMYFUNCTION("""COMPUTED_VALUE"""),272.63) -> 272.63
A18: =IFERROR(__xludf.DUMMYFUNCTION("""COMPUTED_VALUE"""),45923.66666666667) -> 45923.667 | B18: =IFERROR(__xludf.DUMMYFUNCTION("""COMPUTED_VALUE"""),46292.78) -> 46292.78 | C18: =IFERROR(__xludf.DUMMYFUNCTION("""COMPUTED_VALUE"""),45923.66666666667) -> 45923.667 | D18: =IFERROR(__xludf.DUMMYFUNCTION("""COMPUTED_VALUE"""),22573.47) -> 22573.47 | E18: =IFERROR(__xludf.DUMMYFUNCTION("""COMPUTED_VALUE"""),45923.66666666667) -> 45923.667 | F18: =IFERROR(__xludf.DUMMYFUNCTION("""COMPUTED_VALUE"""),6656.92) -> 6656.92 | G18: =IFERROR(__xludf.DUMMYFUNCTION("""COMPUTED_VALUE"""),45923.66666666667) -> 45923.667 | H18: =IFERROR(__xludf.DUMMYFUNCTION("""COMPUTED_VALUE"""),282.71) -> 282.71
A19: =IFERROR(__xludf.DUMMYFUNCTION("""COMPUTED_VALUE"""),45924.66666666667) -> 45924.667 | B19: =IFERROR(__xludf.DUMMYFUNCTION("""COMPUTED_VALUE"""),46121.28) -> 46121.28 | C19: =IFERROR(__xludf.DUMMYFUNCTION("""COMPUTED_VALUE"""),45924.66666666667) -> 45924.667 | D19: =IFERROR(__xludf.DUMMYFUNCTION("""COMPUTED_VALUE"""),22497.86) -> 22497.86 | E19: =IFERROR(__xludf.DUMMYFUNCTION("""COMPUTED_VALUE"""),45924.66666666667) -> 45924.667 | F19: =IFERROR(__xludf.DUMMYFUNCTION("""COMPUTED_VALUE"""),6637.97) -> 6637.97 | G19: =IFERROR(__xludf.DUMMYFUNCTION("""COMPUTED_VALUE"""),45924.66666666667) -> 45924.667 | H19: =IFERROR(__xludf.DUMMYFUNCTION("""COMPUTED_VALUE"""),280.71) -> 280.71
A20: =IFERROR(__xludf.DUMMYFUNCTION("""COMPUTED_VALUE"""),45925.66666666667) -> 45925.667 | B20: =IFERROR(__xludf.DUMMYFUNCTION("""COMPUTED_VALUE"""),45947.32) -> 45947.32 | C20: =IFERROR(__xludf.DUMMYFUNCTION("""COMPUTED_VALUE"""),45925.66666666667) -> 45925.667 | D20: =IFERROR(__xludf.DUMMYFUNCTION("""COMPUTED_VALUE"""),22384.7) -> 22384.7 | E20: =IFERROR(__xludf.DUMMYFUNCTION("""COMPUTED_VALUE"""),45925.66666666667) -> 45925.667 | F20: =IFERROR(__xludf.DUMMYFUNCTION("""COMPUTED_VALUE"""),6604.72) -> 6604.72 | G20: =IFERROR(__xludf.DUMMYFUNCTION("""COMPUTED_VALUE"""),45925.66666666667) -> 45925.667 | H20: =IFERROR(__xludf.DUMMYFUNCTION("""COMPUTED_VALUE"""),276.66) -> 276.66
A21: =IFERROR(__xludf.DUMMYFUNCTION("""COMPUTED_VALUE"""),45926.66666666667) -> 45926.667 | B21: =IFERROR(__xludf.DUMMYFUNCTION("""COMPUTED_VALUE"""),46247.29) -> 46247.29 | C21: =IFERROR(__xludf.DUMMYFUNCTION("""COMPUTED_VALUE"""),45926.66666666667) -> 45926.667 | D21: =IFERROR(__xludf.DUMMYFUNCTION("""COMPUTED_VALUE"""),22484.07) -> 22484.07 | E21: =IFERROR(__xludf.DUMMYFUNCTION("""COMPUTED_VALUE"""),45926.66666666667) -> 45926.667 | F21: =IFERROR(__xludf.DUMMYFUNCTION("""COMPUTED_VALUE"""),6643.7) -> 6643.7 | G21: =IFERROR(__xludf.DUMMYFUNCTION("""COMPUTED_VALUE"""),45926.66666666667) -> 45926.667 | H21: =IFERROR(__xludf.DUMMYFUNCTION("""COMPUTED_VALUE"""),273.36) -> 273.36
A22: =IFERROR(__xludf.DUMMYFUNCTION("""COMPUTED_VALUE"""),45929.66666666667) -> 45929.667 | B22: =IFERROR(__xludf.DUMMYFUNCTION("""COMPUTED_VALUE"""),46316.07) -> 46316.07 | C22: =IFERROR(__xludf.DUMMYFUNCTION("""COMPUTED_VALUE"""),45929.66666666667) -> 45929.667 | D22: =IFERROR(__xludf.DUMMYFUNCTION("""COMPUTED_VALUE"""),22591.15) -> 22591.15 | E22: =IFERROR(__xludf.DUMMYFUNCTION("""COMPUTED_VALUE"""),45929.66666666667) -> 45929.667 | F22: =IFERROR(__xludf.DUMMYFUNCTION("""COMPUTED_VALUE"""),6661.21) -> 6661.21 | G22: =IFERROR(__xludf.DUMMYFUNCTION("""COMPUTED_VALUE"""),45929.66666666667) -> 45929.667 | H22: =IFERROR(__xludf.DUMMYFUNCTION("""COMPUTED_VALUE"""),273.23) -> 273.23
A23: =IFERROR(__xludf.DUMMYFUNCTION("""COMPUTED_VALUE"""),45930.66666666667) -> 45930.667 | B23: =IFERROR(__xludf.DUMMYFUNCTION("""COMPUTED_VALUE"""),46397.89) -> 46397.89 | C23: =IFERROR(__xludf.DUMMYFUNCTION("""COMPUTED_VALUE"""),45930.66666666667) -> 45930.667 | D23: =IFERROR(__xludf.DUMMYFUNCTION("""COMPUTED_VALUE"""),22660.01) -> 22660.01 | E23: =IFERROR(__xludf.DUMMYFUNCTION("""COMPUTED_VALUE"""),45930.66666666667) -> 45930.667 | F23: =IFERROR(__xludf.DUMMYFUNCTION("""COMPUTED_VALUE"""),6688.46) -> 6688.46 | G23: =IFERROR(__xludf.DUMMYFUNCTION("""COMPUTED_VALUE"""),45930.66666666667) -> 45930.667 | H23: =IFERROR(__xludf.DUMMYFUNCTION("""COMPUTED_VALUE"""),279.29) -> 279.29
A24: =IFERROR(__xludf.DUMMYFUNCTION("""COMPUTED_VALUE"""),45931.66666666667) -> 45931.667 | B24: =IFERROR(__xludf.DUMMYFUNCTION("""COMPUTED_VALUE"""),46441.1) -> 46441.1 | C24: =IFERROR(__xludf.DUMMYFUNCTION("""COMPUTED_VALUE"""),45931.66666666667) -> 45931.667 | D24: =IFERROR(__xludf.DUMMYFUNCTION("""COMPUTED_VALUE"""),22755.16) -> 22755.16 | E24: =IFERROR(__xludf.DUMMYFUNCTION("""COMPUTED_VALUE"""),45931.66666666667) -> 45931.667 | F24: =IFERROR(__xludf.DUMMYFUNCTION("""COMPUTED_VALUE"""),6711.2) -> 6711.2 | G24: =IFERROR(__xludf.DUMMYFUNCTION("""COMPUTED_VALUE"""),45931.66666666667) -> 45931.667 | H24: =IFERROR(__xludf.DUMMYFUNCTION("""COMPUTED_VALUE"""),288.47) -> 288.47
A25: =IFERROR(__xludf.DUMMYFUNCTION("""COMPUTED_VALUE"""),45932.66666666667) -> 45932.667 | B25: =IFERROR(__xludf.DUMMYFUNCTION("""COMPUTED_VALUE"""),46519.72) -> 46519.72 | C25: =IFERROR(__xludf.DUMMYFUNCTION("""COMPUTED_VALUE"""),45932.66666666667) -> 45932.667 | D25: =IFERROR(__xludf.DUMMYFUNCTION("""COMPUTED_VALUE"""),22844.05) -> 22844.05 | E25: =IFERROR(__xludf.DUMMYFUNCTION("""COMPUTED_VALUE"""),45932.66666666667) -> 45932.667 | F25: =IFERROR(__xludf.DUMMYFUNCTION("""COMPUTED_VALUE"""),6715.35) -> 6715.35 | G25: =IFERROR(__xludf.DUMMYFUNCTION("""COMPUTED_VALUE"""),45932.66666666667) -> 45932.667 | H25: =IFERROR(__xludf.DUMMYFUNCTION("""COMPUTED_VALUE"""),288.11) -> 288.11
A26: =IFERROR(__xludf.DUMMYFUNCTION("""COMPUTED_VALUE"""),45933.66666666667) -> 45933.667 | B26: =IFERROR(__xludf.DUMMYFUNCTION("""COMPUTED_VALUE"""),46758.28) -> 46758.28 | C26: =IFERROR(__xludf.DUMMYFUNCTION("""COMPUTED_VALUE"""),45933.66666666667) -> 45933.667 | D26: =IFERROR(__xludf.DUMMYFUNCTION("""COMPUTED_VALUE"""),22780.51) -> 22780.51 | E26: =IFERROR(__xludf.DUMMYFUNCTION("""COMPUTED_VALUE"""),45933.66666666667) -> 45933.667 | F26: =IFERROR(__xludf.DUMMYFUNCTION("""COMPUTED_VALUE"""),6715.79) -> 6715.79 | G26: =IFERROR(__xludf.DUMMYFUNCTION("""COMPUTED_VALUE"""),45933.66666666667) -> 45933.667 | H26: =IFERROR(__xludf.DUMMYFUNCTION("""COMPUTED_VALUE"""),292.19) -> 292.19
A27: =IFERROR(__xludf.DUMMYFUNCTION("""COMPUTED_VALUE"""),45936.66666666667) -> 45936.667 | B27: =IFERROR(__xludf.DUMMYFUNCTION("""COMPUTED_VALUE"""),46694.97) -> 46694.97 | C27: =IFERROR(__xludf.DUMMYFUNCTION("""COMPUTED_VALUE"""),45936.66666666667) -> 45936.667 | D27: =IFERROR(__xludf.DUMMYFUNCTION("""COMPUTED_VALUE"""),22941.67) -> 22941.67 | E27: =IFERROR(__xludf.DUMMYFUNCTION("""COMPUTED_VALUE"""),45936.66666666667) -> 45936.667 | F27: =IFERROR(__xludf.DUMMYFUNCTION("""COMPUTED_VALUE"""),6740.28) -> 6740.28 | G27: =IFERROR(__xludf.DUMMYFUNCTION("""COMPUTED_VALUE"""),45936.66666666667) -> 45936.667 | H27: =IFERROR(__xludf.DUMMYFUNCTION("""COMPUTED_VALUE"""),302.4) -> 302.4
A28: =IFERROR(__xludf.DUMMYFUNCTION("""COMPUTED_VALUE"""),45937.66666666667) -> 45937.667 | B28: =IFERROR(__xludf.DUMMYFUNCTION("""COMPUTED_VALUE"""),46602.98) -> 46602.98 | C28: =IFERROR(__xludf.DUMMYFUNCTION("""COMPUTED_VALUE"""),45937.66666666667) -> 45937.667 | D28: =IFERROR(__xludf.DUMMYFUNCTION("""COMPUTED_VALUE"""),22788.36) -> 22788.36 | E28: =IFERROR(__xludf.DUMMYFUNCTION("""COMPUTED_VALUE"""),45937.66666666667) -> 45937.667 | F28: =IFERROR(__xludf.DUMMYFUNCTION("""COMPUTED_VALUE"""),6714.59) -> 6714.59 | G28: =IFERROR(__xludf.DUMMYFUNCTION("""COMPUTED_VALUE"""),45937.66666666667) -> 45937.667 | H28: =IFERROR(__xludf.DUMMYFUNCTION("""COMPUTED_VALUE"""),294.03) -> 294.03
A29: =IFERROR(__xludf.DUMMYFUNCTION("""COMPUTED_VALUE"""),45938.66666666667) -> 45938.667 | B29: =IFERROR(__xludf.DUMMYFUNCTION("""COMPUTED_VALUE"""),46601.78) -> 46601.78 | C29: =IFERROR(__xludf.DUMMYFUNCTION("""COMPUTED_VALUE"""),45938.66666666667) -> 45938.667 | D29: =IFERROR(__xludf.DUMMYFUNCTION("""COMPUTED_VALUE"""),23043.38) -> 23043.38 | E29: =IFERROR(__xludf.DUMMYFUNCTION("""COMPUTED_VALUE"""),45938.66666666667) -> 45938.667 | F29: =IFERROR(__xludf.DUMMYFUNCTION("""COMPUTED_VALUE"""),6753.72) -> 6753.72 | G29: =IFERROR(__xludf.DUMMYFUNCTION("""COMPUTED_VALUE"""),45938.66666666667) -> 45938.667 | H29: =IFERROR(__xludf.DUMMYFUNCTION("""COMPUTED_VALUE"""),304.52) -> 304.52
A30: =IFERROR(__xludf.DUMMYFUNCTION("""COMPUTED_VALUE"""),45939.66666666667) -> 45939.667 | B30: =IFERROR(__xludf.DUMMYFUNCTION("""COMPUTED_VALUE"""),46358.42) -> 46358.42 | C30: =IFERROR(__xludf.DUMMYFUNCTION("""COMPUTED_VALUE"""),45939.66666666667) -> 45939.667 | D30: =IFERROR(__xludf.DUMMYFUNCTION("""COMPUTED_VALUE"""),23024.63) -> 23024.63 | E30: =IFERROR(__xludf.DUMMYFUNCTION("""COMPUTED_VALUE"""),45939.66666666667) -> 45939.667 | F30: =IFERROR(__xludf.DUMMYFUNCTION("""COMPUTED_VALUE"""),6735.11) -> 6735.11 | G30: =IFERROR(__xludf.DUMMYFUNCTION("""COMPUTED_VALUE"""),45939.66666666667) -> 45939.667 | H30: =IFERROR(__xludf.DUMMYFUNCTION("""COMPUTED_VALUE"""),299.88) -> 299.88
A31: =IFERROR(__xludf.DUMMYFUNCTION("""COMPUTED_VALUE"""),45940.66666666667) -> 45940.667 | B31: =IFERROR(__xludf.DUMMYFUNCTION("""COMPUTED_VALUE"""),45479.6) -> 45479.6 | C31: =IFERROR(__xludf.DUMMYFUNCTION("""COMPUTED_VALUE"""),45940.66666666667) -> 45940.667 | D31: =IFERROR(__xludf.DUMMYFUNCTION("""COMPUTED_VALUE"""),22204.43) -> 22204.43 | E31: =IFERROR(__xludf.DUMMYFUNCTION("""COMPUTED_VALUE"""),45940.66666666667) -> 45940.667 | F31: =IFERROR(__xludf.DUMMYFUNCTION("""COMPUTED_VALUE"""),6552.51) -> 6552.51 | G31: =IFERROR(__xludf.DUMMYFUNCTION("""COMPUTED_VALUE"""),45940.66666666667) -> 45940.667 | H31: =IFERROR(__xludf.DUMMYFUNCTION("""COMPUTED_VALUE"""),280.66) -> 280.66
A32: =IFERROR(__xludf.DUMMYFUNCTION("""COMPUTED_VALUE"""),45943.66666666667) -> 45943.667 | B32: =IFERROR(__xludf.DUMMYFUNCTION("""COMPUTED_VALUE"""),46067.58) -> 46067.58 | C32: =IFERROR(__xludf.DUMMYFUNCTION("""COMPUTED_VALUE"""),45943.66666666667) -> 45943.667 | D32: =IFERROR(__xludf.DUMMYFUNCTION("""COMPUTED_VALUE"""),22694.61) -> 22694.61 | E32: =IFERROR(__xludf.DUMMYFUNCTION("""COMPUTED_VALUE"""),45943.66666666667) -> 45943.667 | F32: =IFERROR(__xludf.DUMMYFUNCTION("""COMPUTED_VALUE"""),6654.72) -> 6654.72 | G32: =IFERROR(__xludf.DUMMYFUNCTION("""COMPUTED_VALUE"""),45943.66666666667) -> 45943.667 | H32: =IFERROR(__xludf.DUMMYFUNCTION("""COMPUTED_VALUE"""),302.89) -> 302.89
A33: =IFERROR(__xludf.DUMMYFUNCTION("""COMPUTED_VALUE"""),45944.66666666667) -> 45944.667 | B33: =IFERROR(__xludf.DUMMYFUNCTION("""COMPUTED_VALUE"""),46270.46) -> 46270.46 | C33: =IFERROR(__xludf.DUMMYFUNCTION("""COMPUTED_VALUE"""),45944.66666666667) -> 45944.667 | D33: =IFERROR(__xludf.DUMMYFUNCTION("""COMPUTED_VALUE"""),22521.7) -> 22521.7 | E33: =IFERROR(__xludf.DUMMYFUNCTION("""COMPUTED_VALUE"""),45944.66666666667) -> 45944.667 | F33: =IFERROR(__xludf.DUMMYFUNCTION("""COMPUTED_VALUE"""),6644.31) -> 6644.31 | G33: =IFERROR(__xludf.DUMMYFUNCTION("""COMPUTED_VALUE"""),45944.66666666667) -> 45944.667 | H33: =IFERROR(__xludf.DUMMYFUNCTION("""COMPUTED_VALUE"""),295.94) -> 295.94
A34: =IFERROR(__xludf.DUMMYFUNCTION("""COMPUTED_VALUE"""),45945.66666666667) -> 45945.667 | B34: =IFERROR(__xludf.DUMMYFUNCTION("""COMPUTED_VALUE"""),46253.31) -> 46253.31 | C34: =IFERROR(__xludf.DUMMYFUNCTION("""COMPUTED_VALUE"""),45945.66666666667) -> 45945.667 | D34: =IFERROR(__xludf.DUMMYFUNCTION("""COMPUTED_VALUE"""),22670.08) -> 22670.08 | E34: =IFERROR(__xludf.DUMMYFUNCTION("""COMPUTED_VALUE"""),45945.66666666667) -> 45945.667 | F34: =IFERROR(__xludf.DUMMYFUNCTION("""COMPUTED_VALUE"""),6671.06) -> 6671.06 | G34: =IFERROR(__xludf.DUMMYFUNCTION("""COMPUTED_VALUE"""),45945.66666666667) -> 45945.667 | H34: =IFERROR(__xludf.DUMMYFUNCTION("""COMPUTED_VALUE"""),304.71) -> 304.71
A35: =IFERROR(__xludf.DUMMYFUNCTION("""COMPUTED_VALUE"""),45946.66666666667) -> 45946.667 | B35: =IFERROR(__xludf.DUMMYFUNCTION("""COMPUTED_VALUE"""),45952.24) -> 45952.24 | C35: =IFERROR(__xludf.DUMMYFUNCTION("""COMPUTED_VALUE"""),45946.66666666667) -> 45946.667 | D35: =IFERROR(__xludf.DUMMYFUNCTION("""COMPUTED_VALUE"""),22562.54) -> 22562.54 | E35: =IFERROR(__xludf.DUMMYFUNCTION("""COMPUTED_VALUE"""),45946.66666666667) -> 45946.667 | F35: =IFERROR(__xludf.DUMMYFUNCTION("""COMPUTED_VALUE"""),6629.07) -> 6629.07 | G35: =IFERROR(__xludf.DUMMYFUNCTION("""COMPUTED_VALUE"""),45946.66666666667) -> 45946.667 | H35: =IFERROR(__xludf.DUMMYFUNCTION("""COMPUTED_VALUE"""),299.84) -> 299.84
A36: =IFERROR(__xludf.DUMMYFUNCTION("""COMPUTED_VALUE"""),45947.66666666667) -> 45947.667 | B36: =IFERROR(__xludf.DUMMYFUNCTION("""COMPUTED_VALUE"""),46190.61) -> 46190.61 | C36: =IFERROR(__xludf.DUMMYFUNCTION("""COMPUTED_VALUE"""),45947.66666666667) -> 45947.667 | D36: =IFERROR(__xludf.DUMMYFUNCTION("""COMPUTED_VALUE"""),22679.98) -> 22679.98 | E36: =IFERROR(__xludf.DUMMYFUNCTION("""COMPUTED_VALUE"""),45947.66666666667) -> 45947.667 | F36: =IFERROR(__xludf.DUMMYFUNCTION("""COMPUTED_VALUE"""),6664.01) -> 6664.01 | G36: =IFERROR(__xludf.DUMMYFUNCTION("""COMPUTED_VALUE"""),45947.66666666667) -> 45947.667 | H36: =IFERROR(__xludf.DUMMYFUNCTION("""COMPUTED_VALUE"""),295.08) -> 295.08
A37: =IFERROR(__xludf.DUMMYFUNCTION("""COMPUTED_VALUE"""),45950.66666666667) -> 45950.667 | B37: =IFERROR(__xludf.DUMMYFUNCTION("""COMPUTED_VALUE"""),46706.58) -> 46706.58 | C37: =IFERROR(__xludf.DUMMYFUNCTION("""COMPUTED_VALUE"""),45950.66666666667) -> 45950.667 | D37: =IFERROR(__xludf.DUMMYFUNCTION("""COMPUTED_VALUE"""),22990.54) -> 22990.54 | E37: =IFERROR(__xludf.DUMMYFUNCTION("""COMPUTED_VALUE"""),45950.66666666667) -> 45950.667 | F37: =IFERROR(__xludf.DUMMYFUNCTION("""COMPUTED_VALUE"""),6735.13) -> 6735.13 | G37: =IFERROR(__xludf.DUMMYFUNCTION("""COMPUTED_VALUE"""),45950.66666666667) -> 45950.667 | H37: =IFERROR(__xludf.DUMMYFUNCTION("""COMPUTED_VALUE"""),297.7) -> 297.7
A38: =IFERROR(__xludf.DUMMYFUNCTION("""COMPUTED_VALUE"""),45951.66666666667) -> 45951.667 | B38: =IFERROR(__xludf.DUMMYFUNCTION("""COMPUTED_VALUE"""),46924.74) -> 46924.74 | C38: =IFERROR(__xludf.DUMMYFUNCTION("""COMPUTED_VALUE"""),45951.66666666667) -> 45951.667 | D38: =IFERROR(__xludf.DUMMYFUNCTION("""COMPUTED_VALUE"""),22953.67) -> 22953.67 | E38: =IFERROR(__xludf.DUMMYFUNCTION("""COMPUTED_VALUE"""),45951.66666666667) -> 45951.667 | F38: =IFERROR(__xludf.DUMMYFUNCTION("""COMPUTED_VALUE"""),6735.35) -> 6735.35 | G38: =IFERROR(__xludf.DUMMYFUNCTION("""COMPUTED_VALUE"""),45951.66666666667) -> 45951.667 | H38: =IFERROR(__xludf.DUMMYFUNCTION("""COMPUTED_VALUE"""),294.51) -> 294.51
A39: =IFERROR(__xludf.DUMMYFUNCTION("""COMPUTED_VALUE"""),45952.66666666667) -> 45952.667 | B39: =IFERROR(__xludf.DUMMYFUNCTION("""COMPUTED_VALUE"""),46590.41) -> 46590.41 | C39: =IFERROR(__xludf.DUMMYFUNCTION("""COMPUTED_VALUE"""),45952.66666666667) -> 45952.667 | D39: =IFERROR(__xludf.DUMMYFUNCTION("""COMPUTED_VALUE"""),22740.4) -> 22740.4 | E39: =IFERROR(__xludf.DUMMYFUNCTION("""COMPUTED_VALUE"""),45952.66666666667) -> 45952.667 | F39: =IFERROR(__xludf.DUMMYFUNCTION("""COMPUTED_VALUE"""),6699.4) -> 6699.4 | G39: =IFERROR(__xludf.DUMMYFUNCTION("""COMPUTED_VALUE"""),45952.66666666667) -> 45952.667 | H39: =IFERROR(__xludf.DUMMYFUNCTION("""COMPUTED_VALUE"""),288.88) -> 288.88
A40: =IFERROR(__xludf.DUMMYFUNCTION("""COMPUTED_VALUE"""),45953.66666666667) -> 45953.667 | B40: =IFERROR(__xludf.DUMMYFUNCTION("""COMPUTED_VALUE"""),46734.61) -> 46734.61 | C40: =IFERROR(__xludf.DUMMYFUNCTION("""COMPUTED_VALUE"""),45953.66666666667) -> 45953.667 | D40: =IFERROR(__xludf.DUMMYFUNCTION("""COMPUTED_VALUE"""),22941.8) -> 22941.8 | E40: =IFERROR(__xludf.DUMMYFUNCTION("""COMPUTED_VALUE"""),45953.66666666667) -> 45953.667 | F40: =IFERROR(__xludf.DUMMYFUNCTION("""COMPUTED_VALUE"""),6738.44) -> 6738.44 | G40: =IFERROR(__xludf.DUMMYFUNCTION("""COMPUTED_VALUE"""),45953.66666666667) -> 45953.667 | H40: =IFERROR(__xludf.DUMMYFUNCTION("""COMPUTED_VALUE"""),290.73) -> 290.73
A41: =IFERROR(__xludf.DUMMYFUNCTION("""COMPUTED_VALUE"""),45954.66666666667) -> 45954.667 | B41: =IFERROR(__xludf.DUMMYFUNCTION("""COMPUTED_VALUE"""),47207.12) -> 47207.12 | C41: =IFERROR(__xludf.DUMMYFUNCTION("""COMPUTED_VALUE"""),45954.66666666667) -> 45954.667 | D41: =IFERROR(__xludf.DUMMYFUNCTION("""COMPUTED_VALUE"""),23204.87) -> 23204.87 | E41: =IFERROR(__xludf.DUMMYFUNCTION("""COMPUTED_VALUE"""),45954.66666666667) -> 45954.667 | F41: =IFERROR(__xludf.DUMMYFUNCTION("""COMPUTED_VALUE"""),6791.69) -> 6791.69 | G41: =IFERROR(__xludf.DUMMYFUNCTION("""COMPUTED_VALUE"""),45954.66666666667) -> 45954.667 | H41: =IFERROR(__xludf.DUMMYFUNCTION("""COMPUTED_VALUE"""),294.96) -> 294.96
...

Sheet ChangeLog
A1: 日期 | B1: 內容
A2: 44321.062 | B2: 初始版本，抓取三個月期貨資料，計算 5, 10, 20 平均震幅，計算單位風險
A3: 44321.542 | B3: 計算週一到週五的平均震幅
A4: 2021/05/10 18::30 | B4: 加上期貨預估值
A5: 44328.917 | B5: 修正夜盤問題
A6: 44377.896 | B6: 加上現貨預估值
A7: 44380.771 | B7: 修正結算日問題，更新資訊頁面，可自訂抓取月份數
A8: 44380.875 | B8: 連假時可加總中間所有美股交易日的漲跌幅，來預估開盤值
A9: 44386.375 | B9: 修正 NQ, DJ 漲幅
A10: 44387.583 | B10: 加上使用指南
A11: 44398.375 | B11: 修正 NQ, DJ 漲幅，不用 close，改用 price
A12: 44440.065 | B12: 修正每月第一天收盤前，抓取期貨資料會有錯誤
A13: 44445.065 | B13: 修正週一凌晨 0:00 ~ 04:59 更新會抓到週五夜盤資料
A14: 44482.381 | B14: 修正 NQ, DJ 遇到臺灣連假過後一天的總合漲幅會計算錯誤
A15: 44530.385 | B15: 修正 NQ, DJ 在上一版修正之後，遇到週二早上更新會抓不到資料
A16: 44748.417 | B16: 修正 NQ, DJ
... A21: 44936.625 | B21: 增加目標價震幅
